Workbook

Sheet 00_README
A1: REPRODUCIBLE SOURCE DATA | 11 DESCRIPTIVE FIGURES
A4: Status | B4: Final manuscript-aligned source register: 3 ordinal plots excluded, 11 descriptive plots retained.
A5: Scope | B5: Narrative evidence map from selected references; not a systematic meta-analysis.
A6: Retained figures | B6: S1-S11, renumbered from original S1,S2,S4-S10,S12,S14.
A7: Removed figures | B7: Original S3, S11, S13; 104 related unvalidated scoring decisions omitted.
A8: Results | B8: 339/339 source-to-matrix checks; 11 figures numerically rebuilt.
A9: Consequence | B9: The original Stage2 bibliography [404] is flagged but not yet deleted in this handoff.
A10: Caution | B10: Numeric reproducibility is not independent scientific validation of study-level extraction.
A11: Contents | B11: Code_Sxx records, Matrix_Sxx formula matrices, 09_Recalculation_Check cached audit.
A12: Sources | B12: Source URLs/DOIs in Code_Sxx and Reference_Register; blank DOI is not proof of missing publication.

Sheet 01_Figure_Status
A1: Original figure | B1: New figure | C1: Source table | D1: References (current) | E1: Decision / meaning
A2: S1 | B2: S1 | C2: S1 | D2: 28 | E2: Retained source-coded descriptive category plot
A3: S2 | B3: S2 | C3: S1 | D3: 28 | E3: Retained source-coded descriptive category plot
A4: S3 | B4: REMOVED | C4: S1 | D4: 28 | E4: Unsupported ordinal/hypothetical ranking excluded (author audit separately archived)
A5: S4 | B5: S3 | C5: S2 | D5: 20 | E5: Retained source-coded descriptive category plot
A6: S5 | B6: S4 | C6: S2 | D6: 20 | E6: Retained source-coded descriptive category plot
A7: S6 | B7: S5 | C7: S2 | D7: 20 | E7: Retained source-coded descriptive category plot
A8: S7 | B8: S6 | C8: S3 | D8: 37 | E8: Retained source-coded descriptive category plot
A9: S8 | B9: S7 | C9: S3 | D9: 41 | E9: Retained source-coded descriptive category plot
A10: S9 | B10: S8 | C10: S4 | D10: 45 | E10: Retained source-coded descriptive category plot
A11: S10 | B11: S9 | C11: S4 | D11: 45 | E11: Retained source-coded descriptive category plot
A12: S11 | B12: REMOVED | C12: S5 | D12: 38 | E12: Unsupported ordinal/hypothetical ranking excluded (author audit separately archived)
A13: S12 | B13: S10 | C13: S5 | D13: 34 | E13: Retained source-coded descriptive category plot
... A15: S14 | B15: S11 | C15: S5 | D15: 34 | E15: Retained source-coded descriptive category plot

Sheet 02_Main_475_References
A1: Reference_number | B1: Title_in_manuscript_register | C1: DOI_in_register | D1: Exact_bibliography_entry
A2: 1 | B2: The initiation of oxidative stress and therapeutic strategies in wound healing | C2: 10.1016/j.biopha.2022.114004 | D2: Wang, G., et al., The initiation of oxidative stress and therapeutic strategies in wound healing. Biomedicine & Pharmacotherapy, 2023. 157: p. 114004.
A3: 2 | B3: Human wound and its burden: Updated 2025 compendium of estimates | C3: 10.1177/21621918251359554 | D3: Sen, C.K., Human wound and its burden: Updated 2025 compendium of estimates. 2025, SAGE Publications Sage CA: Los Angeles, CA. p. 429–438.
A4: 3 | B4: Challenges and new therapeutic approaches in the management of chronic wounds | C4: 10.2174/1389450121666200623131200 | D4: Sun, H., L. Pulakat, and D.W. Anderson, Challenges and new therapeutic approaches in the management of chronic wounds. Current drug targets, 2020. 21(12): p. 1264–1275.
A5: 4 | B5: Healing of chronic wounds: an update of recent developments and future possibilities | C5: 10.1089/ten.TEB.2019.0019 | D5: Kathawala, M.H., et al., Healing of chronic wounds: an update of recent developments and future possibilities. Tissue Engineering Part B: Reviews, 2019. 25(5): p. 429–444.
A6: 5 | B6: The discovery and development of topical medicines for wound healing | C6: 10.1080/17460441.2019.1588879 | D6: Öhnstedt, E., et al., The discovery and development of topical medicines for wound healing. Expert opinion on drug discovery, 2019. 14(5): p. 485–497.
A7: 6 | B7: Innovative treatment strategies to accelerate wound healing: trajectory and recent advancements | C7: 10.3390/cells11152439 | D7: Kolimi, P., et al., Innovative treatment strategies to accelerate wound healing: trajectory and recent advancements. Cells, 2022. 11(15): p. 2439.
A8: 7 | B8: Clinically Unmet Needs of Conventional Diabetic Foot Ulcer Dressings | C8: 10.1021/acsmaterialslett.5c00971 | D8: Hsu, C.-W.R., et al., Clinically Unmet Needs of Conventional Diabetic Foot Ulcer Dressings. ACS Materials Letters, 2025. 8(1): p. 2–15.
A9: 8 | B9: Food and Drug Administration perspective: Advancing product development for non‐healing chronic wounds | C9: 10.1111/wrr.13008 | D9: Verma, K.D., et al., Food and Drug Administration perspective: Advancing product development for non‐healing chronic wounds. Wound Repair and Regeneration, 2022. 30(3): p. 299–302.
A10: 9 | B10: Limited treatment options for diabetic wounds: barriers to clinical translation despite therapeutic success in murine models | C10: 10.1089/wound.2020.1254 | D10: Barakat, M., L.A. DiPietro, and L. Chen, Limited treatment options for diabetic wounds: barriers to clinical translation despite therapeutic success in murine models. Advances in Wound Care, 2021. 10(8): p. 436–460.
A11: 10 | B11: Translational development of ABCB5+ dermal mesenchymal stem cells for therapeutic induction of angiogenesis in non-healing diabetic foot ulcers | C11: 10.1186/s13287-022-03156-9 | D11: Kerstan, A., et al., Translational development of ABCB5+ dermal mesenchymal stem cells for therapeutic induction of angiogenesis in non-healing diabetic foot ulcers. Stem cell research & therapy, 2022. 13(1): p. 455.
A12: 11 | B12: Challenges faced in developing an ideal chronic wound model | C12: 10.1080/17460441.2023.2158809 | D12: Tan, M.L.L., et al., Challenges faced in developing an ideal chronic wound model. Expert opinion on drug discovery, 2023. 18(1): p. 99–114.
A13: 12 | B13: Advances in, and prospects of, 3D preclinical models for skin drug discovery | C13: 10.1016/j.drudis.2024.104208 | D13: Imran, M., et al., Advances in, and prospects of, 3D preclinical models for skin drug discovery. Drug Discovery Today, 2024. 29(12): p. 104208.
... A24: 23 | B24: Machine learning combining external validation to explore the immunopathogenesis of diabetic foot ulcer and predict therapeutic drugs | C24: 10.1371/journal.pone.0328906 | D24: Lu, Z., et al., Machine learning combining external validation to explore the immunopathogenesis of diabetic foot ulcer and predict therapeutic drugs. Plos one, 2025. 20(8): p. e0328906.
A25: 24 | B25: Microfluidic skin‐on‐a‐chip models: Toward biomimetic artificial skin | D25: Sutterby, E., et al., Microfluidic skin‐on‐a‐chip models: Toward biomimetic artificial skin. Small, 2020. 16(39): p. 2002515.
A26: 25 | B26: Fibroblast derived skin wound healing modeling on chip under the influence of micro-capillary shear stress | D26: Gupta, S., et al., Fibroblast derived skin wound healing modeling on chip under the influence of micro-capillary shear stress. Micromachines, 2022. 13(2): p. 305.
A27: 26 | B27: Full-thickness perfused skin-on-a-chip with in vivo-like drug response for drug and cosmetics testing | D27: Rhee, S., et al., Full-thickness perfused skin-on-a-chip with in vivo-like drug response for drug and cosmetics testing. Bioengineering, 2024. 11(11): p. 1055.
A28: 27 | B28: Smart closed-loop drug delivery systems | D28: Paci, M.M., et al., Smart closed-loop drug delivery systems. Nature Reviews Bioengineering, 2025. 3(10): p. 816–834.
A29: 28 | B29: Human relevant platforms for cutaneous wound healing research: current landscape, translational gaps, and emerging frontiers | C29: 10.3389/fbioe.2026.1917429 | D29: Latheef, F. and K. Suthindhiran, Human relevant platforms for cutaneous wound healing research: current landscape, translational gaps, and emerging frontiers. Frontiers in Bioengineering and Biotechnology, 2026. 14: p. 1917429.
A30: 29 | B30: Advances in skin-on-a-chip technology: functional innovations and translational challenges | C30: 10.1016/j.trac.2025.118500 | D30: Zhang, J., et al., Advances in skin-on-a-chip technology: functional innovations and translational challenges. TrAC Trends in Analytical Chemistry, 2025: p. 118500.
A31: 30 | B31: Bio-inks for skin regeneration: phase-adaptive design, multifunctional platforms, and 4D bioprinting frontiers | C31: 10.3389/fbioe.2026.1919338 | D31: Bahrami, G., et al., Bio-inks for skin regeneration: phase-adaptive design, multifunctional platforms, and 4D bioprinting frontiers. Frontiers in Bioengineering and Biotechnology, 2026. 14: p. 1919338.
A32: 31 | B32: The synergy of artificial intelligence and organ-on-a-chip: building a next-generation intelligent engine for drug development | C32: 10.1016/j.ijpharm.2026.127339 | D32: Yong, Q., et al., The synergy of artificial intelligence and organ-on-a-chip: building a next-generation intelligent engine for drug development. International Journal of Pharmaceutics, 2026: p. 127339.
A33: 32 | B33: Wound healing: cellular mechanisms and pathological outcomes | C33: 10.1098/rsob.200223 | D33: Wilkinson, H.N. and M.J. Hardman, Wound healing: cellular mechanisms and pathological outcomes. Open biology, 2020. 10(9).
A34: 33 | B34: Immunology of acute and chronic wound healing | C34: 10.3390/biom11050700 | D34: Raziyeva, K., et al., Immunology of acute and chronic wound healing. Biomolecules, 2021. 11(5): p. 700.
A35: 34 | B35: Emerging Technologies and Solutions for Chronic Wound Care and Diagnosis | D35: Matoori, S. and E. Engel, Emerging Technologies and Solutions for Chronic Wound Care and Diagnosis. 2025, ACS Publications. p. 1435–1437.
A36: 35 | B36: The impact of prolonged inflammation on wound healing | D36: Holzer-Geissler, J.C., et al., The impact of prolonged inflammation on wound healing. Biomedicines, 2022. 10(4): p. 856.
A37: 36 | B37: Deregulated immune cell recruitment orchestrated by FOXM1 impairs human diabetic wound healing | D37: Sawaya, A.P., et al., Deregulated immune cell recruitment orchestrated by FOXM1 impairs human diabetic wound healing. Nature communications, 2020. 11(1): p. 4678.
A38: 37 | B38: The epidermal keratinocyte as a therapeutic target for management of diabetic wounds | D38: Fang, W.-C. and C.-C.E. Lan, The epidermal keratinocyte as a therapeutic target for management of diabetic wounds. International Journal of Molecular Sciences, 2023. 24(5): p. 4290.
A39: 38 | B39: Keratinocyte function in normal and diabetic wounds and modulation by FOXO1 | D39: Wang, Y. and D.T. Graves, Keratinocyte function in normal and diabetic wounds and modulation by FOXO1. Journal of Diabetes Research, 2020. 2020(1): p. 3714704.
A40: 39 | B40: Amniotic epithelial cells accelerate diabetic wound healing by protecting keratinocytes and fibroblasts from high‐glucose‐induced senescence | D40: Shu, F., et al., Amniotic epithelial cells accelerate diabetic wound healing by protecting keratinocytes and fibroblasts from high‐glucose‐induced senescence. Cell Biology International, 2022. 46(5): p. 755–770.
A41: 40 | B41: EGCG restores keratinocyte autophagy to promote diabetic wound healing through the AMPK/ULK1 pathway | D41: Tian, C., et al., EGCG restores keratinocyte autophagy to promote diabetic wound healing through the AMPK/ULK1 pathway. Frontiers in Bioscience-Landmark, 2023. 28(12): p. 324.
A42: 41 | B42: Human wound and its burden: updated 2022 compendium of estimates | D42: Sen, C.K., Human wound and its burden: updated 2022 compendium of estimates. 2023, SAGE Publications Sage CA: Los Angeles, CA. p. 657–670.
A43: 42 | B43: Fibroblasts in diabetic foot ulcers | D43: Voza, F.A., et al., Fibroblasts in diabetic foot ulcers. International journal of molecular sciences, 2024. 25(4): p. 2172.
A44: 43 | B44: Diabetic wound healing: The impact of diabetes on myofibroblast activity and its potential therapeutic treatments | D44: Wan, R., et al., Diabetic wound healing: The impact of diabetes on myofibroblast activity and its potential therapeutic treatments. Wound Repair and Regeneration, 2021. 29(4): p. 573–581.
A45: 44 | B45: Fibroblast Dysfunction and Immune Dysregulation Impair Palatal Wound Healing in Diabetic Rats | D45: Pan, L., et al., Fibroblast Dysfunction and Immune Dysregulation Impair Palatal Wound Healing in Diabetic Rats. International Dental Journal, 2025. 75(6): p. 103894.
A46: 45 | B46: Macrophage dysregulation and impaired skin wound healing in diabetes | D46: Barman, P.K. and T.J. Koh, Macrophage dysregulation and impaired skin wound healing in diabetes. Frontiers in cell and developmental biology, 2020. 8: p. 528.
... A91: 90 | B91: Engineering bioactive M2 macrophage‐polarized anti‐inflammatory, antioxidant, and antibacterial scaffolds for rapid angiogenesis and diabetic wound repair | D91: Tu, Z., et al., Engineering bioactive M2 macrophage‐polarized anti‐inflammatory, antioxidant, and antibacterial scaffolds for rapid angiogenesis and diabetic wound repair. Advanced Functional Materials, 2021. 31(30): p. 2100924.
A92: 91 | B92: Promising Biomarkers for Chronic Wound Healing: A Pilot Cohort Study on Wound Cytokines and a Novel Biofilm Detection Kit for Predicting 90‐Day Outcomes | C92: 10.1111/wrr.70100 | D92: Wu, Y.F., et al., Promising Biomarkers for Chronic Wound Healing: A Pilot Cohort Study on Wound Cytokines and a Novel Biofilm Detection Kit for Predicting 90‐Day Outcomes. Wound Repair and Regeneration, 2025. 33(5): p. e70100.
A93: 92 | B93: Compromised angiogenesis and vascular Integrity in impaired diabetic wound healing | D93: Okonkwo, U.A., et al., Compromised angiogenesis and vascular Integrity in impaired diabetic wound healing. PloS one, 2020. 15(4): p. e0231962.
A94: 93 | B94: Diabetes and wound angiogenesis | D94: Okonkwo, U.A. and L.A. DiPietro, Diabetes and wound angiogenesis. International journal of molecular sciences, 2017. 18(7): p. 1419.
...

Sheet 03_SI_Table_Cohorts
A1: SI_Table | B1: Reference_number | C1: SI_Table_row_identification | D1: Title_from_main | E1: DOI_from_register
A2: S1 | B2: 105 | C2: 2: Migration assay standardization | D2: Comparison of in vitro scratch wound assay experimental procedures | E2: 10.1016/j.bbrep.2023.101423
A3: S1 | B3: 106 | C3: 4: 2D assays with acute in vivo validation | D3: ERK activating peptide, AES16-2M promotes wound healing through accelerating migration of keratinocytes | E3: 10.1038/s41598-018-32851-y
A4: S1 | B4: 107 | C4: 3: 2D therapeutic-response assays | D4: Effects of Periploca forrestii Schltr on wound healing by Src meditated Mek/Erk and PI3K/Akt signals | E4: 10.1016/j.jep.2019.03.046
A5: S1 | B5: 108 | C5: 2: Migration assay standardization | D5: Microscopy based methods for the assessment of epithelial cell migration during in vitro wound healing | E5: 10.3791/56799
A6: S1 | B6: 109 | C6: 3: 2D therapeutic-response assays | D6: Establishment of a cell-based wound healing assay for bio-relevant testing of wound therapeutics | E6: 10.1016/j.vascn.2017.10.003
A7: S1 | B7: 110 | C7: 6: Reconstructed epidermis for barrier and irritation testing | D7: Property characterization of reconstructed human epidermis equivalents, and performance as a skin irritation model | E7: 10.1016/j.tiv.2018.07.005
A8: S1 | B8: 111 | C8: 6: Reconstructed epidermis for barrier and irritation testing | D8: A new reconstructed human epidermis for in vitro skin irritation testing | E8: 10.1016/j.tiv.2017.03.010
A9: S1 | B9: 112 | C9: 7: Epidermal and full-thickness toxicity comparison | D9: Skin corrosion test: A comparison between reconstructed human epidermis and full thickness skin models | E9: 10.1016/j.ejpb.2018.01.002
A10: S1 | B10: 115 | C10: 7: Epidermal and full-thickness toxicity comparison | D10: Skin toxicity assessment of silver nanoparticles in a 3D epidermal model compared to 2D keratinocytes | E10: 10.2147/IJN.S225451
A11: S1 | B11: 118 | C11: 11: Longitudinal non-invasive wound monitoring | D11: New Methodological Approach to Follow the Re‐Epithelialisation Phase in the Wound Healing Process on a 3D Full Thickness Skin Model | E11: 10.1111/exd.70137
A12: S1 | B12: 119 | C12: 8: Automated epidermal digital pathology | D12: Assessment of skin toxicity in an in vitro reconstituted human epidermis model using deep learning | E12: 10.1016/j.ajpath.2021.12.007
A13: S1 | B13: 122 | C13: 10: Matrix-based 3D wound constructs | D13: Keratinocyte migration in a three-dimensional in vitro wound healing model co-cultured with fibroblasts | E13: 10.1007/s13770-018-0145-7
... A29: S1 | B29: 142 | C29: 19: Disease-relevant diabetic bioprinted skin | D29: Engineering of diseased human skin equivalent using 3D cell printing for representing pathophysiological hallmarks of type 2 diabetes in vitro | E29: 10.1016/j.biomaterials.2021.120776
A30: S2 | B30: 58 | C30: 12: Perfused inflammatory full-thickness skin-on-chip model for drug-response testing | D30: Analysis of drug efficacy for inflammatory skin on an organ-chip system
A31: S2 | B31: 101 | C31: 18: Multiplexed wound-exudate sensing patches | D31: A flexible multiplexed immunosensor for point-of-care in situ wound monitoring | E31: 10.1126/sciadv.abg9614
A32: S2 | B32: 155 | C32: 2: Perfused dermal perivascular angiogenesis chip | D32: A 3D millifluidic model of a dermal perivascular microenvironment on a chip | E32: 10.1039/d4lc00898g
A33: S2 | B33: 158 | C33: 3: Ex vivo full-thickness human skin microbioreactor | D33: Design and evaluation of a skin-on-a-chip pumpless microfluidic device | E33: 10.1038/s41598-023-34796-3
A34: S2 | B34: 159 | C34: 4: Layered tissue-generation chip | D34: A new microfluidic method enabling the generation of multi-layered tissues-on-chips using skin cells as a proof of concept | E34: 10.1038/s41598-021-91875-z
A35: S2 | B35: 164 | C35: 5: Oxygen-gradient angiogenesis module | D35: Studying sprouting angiogenesis under combination of oxygen gradients and co-culture of fibroblasts using microfluidic cell culture model | E35: 10.1016/j.mtbio.2023.100703
A36: S2 | B36: 166 | C36: 7: Perfused reconstructed skin-on-chip for transdermal diffusion | D36: In silico approach for validating organ-on-chips: exemplifying through a skin-on-chip device | E36: 10.1007/s10404-025-02863-y
A37: S2 | B37: 169 | C37: 13: Infection-activated vessel-on-chip | D37: An in vitro human vessel model to study Neisseria meningitidis colonization and vascular damages | E37: 10.7554/eLife.107813
A38: S2 | B38: 181 | C38: 8: Perfused 3D skin-on-chip for barrier validation and drug permeation | D38: A 3D microfluidic model for preclinical drug permeation studies: Advancing validation of skin-on-chip technology | E38: 10.1016/j.jpba.2025.117187
A39: S2 | B39: 182 | C39: 18: Multiplexed wound-exudate sensing patches | D39: A flexible and multimodal biosensing patch integrated with microfluidics for chronic wound monitoring | E39: 10.1016/j.cej.2024.157673
A40: S2 | B40: 183 | C40: 19: Battery-free lactate prognostic wound monitor | D40: A miniaturized, battery‐free, wireless wound monitor that predicts wound closure rate early | E40: 10.1002/adhm.202301280
A41: S2 | B41: 187 | C41: 21: Wireless smart bandage with sensing and electrical stimulation | D41: Wireless, closed-loop, smart bandage with integrated sensors and stimulators for advanced wound care and accelerated healing | E41: 10.1038/s41587-022-01528-3
A42: S2 | B42: 188 | C42: 22: Closed-loop wound-management platform with on-chip inference and drug delivery | D42: Smart Wound Management System Capable of On‐Chip Machine Learning and Closed‐Loop Therapeutic Feedback | E42: 10.1002/adfm.202522329
... A47: S2 | B47: 196 | C47: 14: Dynamic reconstructed skin-on-chip for topical sensitizer response | D47: Proof-of-concept organ-on-chip study: topical cinnamaldehyde exposure of reconstructed human skin with integrated neopapillae cultured under dynamic flow | E47: 10.3390/pharmaceutics14081529
A48: S2 | B48: 197 | C48: 15: Perfused inflammatory skin-on-chip with rapid cytokine detection | D48: Skin-on-a-Chip Coupled with a Rapid Inflammation Detection System for Cosmetic Ingredient Screening
A49: S2 | B49: 198 | C49: 16: Epidermal pruritus and barrier-support skin-on-chip | D49: Skin-on-Chip and clinical evaluation of the soothing potential of a topical natural treatment for atopic-prone skin: An exploratory study | E49: 10.1016/j.biopha.2025.118957
A50: S3 | B50: 200 | C50: 3: Redox-, glucose-, and mixed-stimulus adaptive hydrogels | D50: Construction of oxidized dextran-based pH/ROS responsive hydrogel with live bacterial microcapsules for accelerating diabetic wound healing via reducing inflammatory factors | E50: 10.1016/j.ijbiomac.2026.151405
A51: S3 | B51: 201 | C51: 3: Redox-, glucose-, and mixed-stimulus adaptive hydrogels | D51: pH/ROS responsive hydrogel loaded with bimetallic phenolic nanoparticles: A multifaceted therapeutic strategy for accelerating diabetic wound repair | E51: 10.1016/j.cej.2025.170173
A52: S3 | B52: 202 | C52: 4: Enzyme-activated infection and remodeling depots | D52: Bacterial enzyme-responsive hydrogels for triggered delivery of antibiotics to infected wounds | E52: 10.1126/sciadv.adz0786
A53: S3 | B53: 206 | C53: 2: Acidic pH-switching adhesive and release matrices | D53: pH-responsive hydrogel loaded with insulin as a bioactive dressing for enhancing diabetic wound healing | E53: 10.1016/j.matdes.2021.110104
A54: S3 | B54: 207 | C54: 2: Acidic pH-switching adhesive and release matrices | D54: Dual-crosslinked mussel-inspired smart hydrogels with enhanced antibacterial and angiogenic properties for chronic infected diabetic wound treatment via pH-responsive quick cargo release | E54: 10.1016/j.cej.2021.128564
A55: S3 | B55: 210 | C55: 3: Redox-, glucose-, and mixed-stimulus adaptive hydrogels | D55: ROS-scavenging hydrogel to promote healing of bacteria infected diabetic wounds | E55: 10.1016/j.biomaterials.2020.120286
A56: S3 | B56: 211 | C56: 3: Redox-, glucose-, and mixed-stimulus adaptive hydrogels | D56: Ros-responsive hydrogel with size-dependent sequential release effects for anti-bacterial and anti-inflammation in diabetic wound healing
A57: S3 | B57: 212 | C57: 3: Redox-, glucose-, and mixed-stimulus adaptive hydrogels | D57: Smart multifunctional ROS-responsive supramolecular hydrogel for simultaneously regulating oxidative stress, immune dysregulation, and bacterial infection in diabetic wound healing | E57: 10.1016/j.biomaterials.2026.124006
A58: S3 | B58: 214 | C58: 3: Redox-, glucose-, and mixed-stimulus adaptive hydrogels | D58: A smart ROS-responsive hydrogel for on-demand antibacterial and platelet-rich plasma (PRP) activation in diabetic wound healing | E58: 10.1016/j.jconrel.2025.114392
A59: S3 | B59: 215 | C59: 3: Redox-, glucose-, and mixed-stimulus adaptive hydrogels | D59: Glucose/ROS-responsive and redox-gated adaptive hydrogel dressing for accelerating diabetic wound repair via synergistic cGAS/STING pathway inhibition and oxidative stress alleviation | E59: 10.1016/j.bioactmat.2026.03.025
...

Sheet 08_Study_Cohorts
A1: Figure | B1: Main ref | C1: Group
A2: S1 | B2: 105 | C2: 2D early screening models
A3: S1 | B3: 106 | C3: 2D early screening models
A4: S1 | B4: 107 | C4: 2D early screening models
A5: S1 | B5: 108 | C5: 2D early screening models
A6: S1 | B6: 109 | C6: 2D early screening models
A7: S1 | B7: 110 | C7: 3D epidermal models
A8: S1 | B8: 111 | C8: 3D epidermal models
A9: S1 | B9: 112 | C9: 3D epidermal models
A10: S1 | B10: 115 | C10: 3D epidermal models
A11: S1 | B11: 118 | C11: 3D wound models
A12: S1 | B12: 119 | C12: 3D epidermal models
A13: S1 | B13: 122 | C13: 3D wound models
... A97: S4 | B97: 198 | C97: Disease/immune programming
A98: S5 | B98: 58
A99: S5 | B99: 101
A100: S5 | B100: 155
A101: S5 | B101: 158
A102: S5 | B102: 159
A103: S5 | B103: 164
A104: S5 | B104: 166
A105: S5 | B105: 169
A106: S5 | B106: 181
A107: S5 | B107: 182
A108: S5 | B108: 183
A109: S5 | B109: 187
... A117: S5 | B117: 198
A118: S6 | B118: 200 | C118: ROS/redox-responsive
A119: S6 | B119: 200 | C119: pH-responsive
A120: S6 | B120: 201 | C120: ROS/redox-responsive
A121: S6 | B121: 201 | C121: Thermo/NIR or externally actuated
A122: S6 | B122: 201 | C122: pH-responsive
A123: S6 | B123: 202 | C123: Enzyme-responsive
A124: S6 | B124: 206 | C124: Sustained or staged delivery
A125: S6 | B125: 206 | C125: pH-responsive
A126: S6 | B126: 207 | C126: pH-responsive
A127: S6 | B127: 210 | C127: ROS/redox-responsive
A128: S6 | B128: 211 | C128: ROS/redox-responsive
A129: S6 | B129: 211 | C129: Thermo/NIR or externally actuated
... A297: S9 | B297: 353 | C297: AI-ready smart sensing and closed-loop therapeutic platforms
...

Sheet Code_S01
A1: Main_ref | B1: SI_source_table | C1: SI_table_row | D1: Main_article_title | E1: DOI_in_main_register | F1: Group | G1: Domain | H1: Code_0_1 | I1: Proposed_structural_score | J1: Proposed_disease_score | K1: Provenance_note | L1: Source_URL | M1: Bibliography_title_match_pct | N1: Citation_present_in_main
A2: 105 | B2: S1 | C2: 2: Migration assay standardization | D2: Comparison of in vitro scratch wound assay experimental procedures | E2: 10.1016/j.bbrep.2023.101423 | F2: 2D early screening models | G2: Longitudinal/time-resolved | H2: 1 | K2: From 28-study Table S1 source extraction; zero means not evidenced in extracted record | L2: https://pmc.ncbi.nlm.nih.gov/articles/PMC9840221/ | M2: 100.0 | N2: YES
A3: 105 | B3: S1 | C3: 2: Migration assay standardization | D3: Comparison of in vitro scratch wound assay experimental procedures | E3: 10.1016/j.bbrep.2023.101423 | F3: 2D early screening models | G3: Image/segmentation | H3: 1 | K3: From 28-study Table S1 source extraction; zero means not evidenced in extracted record | L3: https://pmc.ncbi.nlm.nih.gov/articles/PMC9840221/ | M3: 100.0 | N3: YES
A4: 105 | B4: S1 | C4: 2: Migration assay standardization | D4: Comparison of in vitro scratch wound assay experimental procedures | E4: 10.1016/j.bbrep.2023.101423 | F4: 2D early screening models | G4: Barrier/permeability | H4: 0 | K4: From 28-study Table S1 source extraction; zero means not evidenced in extracted record | L4: https://pmc.ncbi.nlm.nih.gov/articles/PMC9840221/ | M4: 100.0 | N4: YES
A5: 105 | B5: S1 | C5: 2: Migration assay standardization | D5: Comparison of in vitro scratch wound assay experimental procedures | E5: 10.1016/j.bbrep.2023.101423 | F5: 2D early screening models | G5: Molecular/inflammatory | H5: 0 | K5: From 28-study Table S1 source extraction; zero means not evidenced in extracted record | L5: https://pmc.ncbi.nlm.nih.gov/articles/PMC9840221/ | M5: 100.0 | N5: YES
A6: 105 | B6: S1 | C6: 2: Migration assay standardization | D6: Comparison of in vitro scratch wound assay experimental procedures | E6: 10.1016/j.bbrep.2023.101423 | F6: 2D early screening models | G6: Histology/IHC | H6: 0 | K6: From 28-study Table S1 source extraction; zero means not evidenced in extracted record | L6: https://pmc.ncbi.nlm.nih.gov/articles/PMC9840221/ | M6: 100.0 | N6: YES
A7: 105 | B7: S1 | C7: 2: Migration assay standardization | D7: Comparison of in vitro scratch wound assay experimental procedures | E7: 10.1016/j.bbrep.2023.101423 | F7: 2D early screening models | G7: Mechanical/material | H7: 0 | K7: From 28-study Table S1 source extraction; zero means not evidenced in extracted record | L7: https://pmc.ncbi.nlm.nih.gov/articles/PMC9840221/ | M7: 100.0 | N7: YES
A8: 105 | B8: S1 | C8: 2: Migration assay standardization | D8: Comparison of in vitro scratch wound assay experimental procedures | E8: 10.1016/j.bbrep.2023.101423 | F8: 2D early screening models | G8: Vascular/perfusion | H8: 0 | K8: From 28-study Table S1 source extraction; zero means not evidenced in extracted record | L8: https://pmc.ncbi.nlm.nih.gov/articles/PMC9840221/ | M8: 100.0 | N8: YES
A9: 106 | B9: S1 | C9: 4: 2D assays with acute in vivo validation | D9: ERK activating peptide, AES16-2M promotes wound healing through accelerating migration of keratinocytes | E9: 10.1038/s41598-018-32851-y | F9: 2D early screening models | G9: Longitudinal/time-resolved | H9: 1 | K9: From 28-study Table S1 source extraction; zero means not evidenced in extracted record | L9: https://www.nature.com/articles/s41598-018-32851-y | M9: 100.0 | N9: YES
A10: 106 | B10: S1 | C10: 4: 2D assays with acute in vivo validation | D10: ERK activating peptide, AES16-2M promotes wound healing through accelerating migration of keratinocytes | E10: 10.1038/s41598-018-32851-y | F10: 2D early screening models | G10: Image/segmentation | H10: 1 | K10: From 28-study Table S1 source extraction; zero means not evidenced in extracted record | L10: https://www.nature.com/articles/s41598-018-32851-y | M10: 100.0 | N10: YES
A11: 106 | B11: S1 | C11: 4: 2D assays with acute in vivo validation | D11: ERK activating peptide, AES16-2M promotes wound healing through accelerating migration of keratinocytes | E11: 10.1038/s41598-018-32851-y | F11: 2D early screening models | G11: Barrier/permeability | H11: 0 | K11: From 28-study Table S1 source extraction; zero means not evidenced in extracted record | L11: https://www.nature.com/articles/s41598-018-32851-y | M11: 100.0 | N11: YES
A12: 106 | B12: S1 | C12: 4: 2D assays with acute in vivo validation | D12: ERK activating peptide, AES16-2M promotes wound healing through accelerating migration of keratinocytes | E12: 10.1038/s41598-018-32851-y | F12: 2D early screening models | G12: Molecular/inflammatory | H12: 1 | K12: From 28-study Table S1 source extraction; zero means not evidenced in extracted record | L12: https://www.nature.com/articles/s41598-018-32851-y | M12: 100.0 | N12: YES
A13: 106 | B13: S1 | C13: 4: 2D assays with acute in vivo validation | D13: ERK activating peptide, AES16-2M promotes wound healing through accelerating migration of keratinocytes | E13: 10.1038/s41598-018-32851-y | F13: 2D early screening models | G13: Histology/IHC | H13: 1 | K13: From 28-study Table S1 source extraction; zero means not evidenced in extracted record | L13: https://www.nature.com/articles/s41598-018-32851-y | M13: 100.0 | N13: YES
... A197: 142 | B197: S1 | C197: 19: Disease-relevant diabetic bioprinted skin | D197: Engineering of diseased human skin equivalent using 3D cell printing for representing pathophysiological hallmarks of type 2 diabetes in vitro | E197: 10.1016/j.biomaterials.2021.120776 | F197: Bioprinted models | G197: Vascular/perfusion | H197: 1 | K197: From 28-study Table S1 source extraction; zero means not evidenced in extracted record | L197: https://pubmed.ncbi.nlm.nih.gov/33798956/ | M197: 100.0 | N197: YES

Sheet Matrix_S01
A1: Model class | B1: Longitudinal/time-resolved | C1: Image/segmentation | D1: Barrier/permeability | E1: Molecular/inflammatory | F1: Histology/IHC | G1: Mechanical/material | H1: Vascular/perfusion | I1: Unique studies in class
A2: 2D early screening models | B2: =COUNTIFS('Code_S01'!$F$2:$F$197,SUBSTITUTE($A2,CHAR(10)," "),'Code_S01'!$G$2:$G$197,SUBSTITUTE(B$1,CHAR(10)," "),'Code_S01'!$H$2:$H$197,1) -> 4 | C2: =COUNTIFS('Code_S01'!$F$2:$F$197,SUBSTITUTE($A2,CHAR(10)," "),'Code_S01'!$G$2:$G$197,SUBSTITUTE(C$1,CHAR(10)," "),'Code_S01'!$H$2:$H$197,1) -> 5 | D2: =COUNTIFS('Code_S01'!$F$2:$F$197,SUBSTITUTE($A2,CHAR(10)," "),'Code_S01'!$G$2:$G$197,SUBSTITUTE(D$1,CHAR(10)," "),'Code_S01'!$H$2:$H$197,1) -> 0 | E2: =COUNTIFS('Code_S01'!$F$2:$F$197,SUBSTITUTE($A2,CHAR(10)," "),'Code_S01'!$G$2:$G$197,SUBSTITUTE(E$1,CHAR(10)," "),'Code_S01'!$H$2:$H$197,1) -> 4 | F2: =COUNTIFS('Code_S01'!$F$2:$F$197,SUBSTITUTE($A2,CHAR(10)," "),'Code_S01'!$G$2:$G$197,SUBSTITUTE(F$1,CHAR(10)," "),'Code_S01'!$H$2:$H$197,1) -> 3 | G2: =COUNTIFS('Code_S01'!$F$2:$F$197,SUBSTITUTE($A2,CHAR(10)," "),'Code_S01'!$G$2:$G$197,SUBSTITUTE(G$1,CHAR(10)," "),'Code_S01'!$H$2:$H$197,1) -> 0 | H2: =COUNTIFS('Code_S01'!$F$2:$F$197,SUBSTITUTE($A2,CHAR(10)," "),'Code_S01'!$G$2:$G$197,SUBSTITUTE(H$1,CHAR(10)," "),'Code_S01'!$H$2:$H$197,1) -> 1 | I2: =COUNTIFS('08_Study_Cohorts'!$A$2:$A$365,"S1",'08_Study_Cohorts'!$C$2:$C$365,SUBSTITUTE($A2,CHAR(10)," ")) -> 5
A3: 3D epidermal models | B3: =COUNTIFS('Code_S01'!$F$2:$F$197,SUBSTITUTE($A3,CHAR(10)," "),'Code_S01'!$G$2:$G$197,SUBSTITUTE(B$1,CHAR(10)," "),'Code_S01'!$H$2:$H$197,1) -> 0 | C3: =COUNTIFS('Code_S01'!$F$2:$F$197,SUBSTITUTE($A3,CHAR(10)," "),'Code_S01'!$G$2:$G$197,SUBSTITUTE(C$1,CHAR(10)," "),'Code_S01'!$H$2:$H$197,1) -> 5 | D3: =COUNTIFS('Code_S01'!$F$2:$F$197,SUBSTITUTE($A3,CHAR(10)," "),'Code_S01'!$G$2:$G$197,SUBSTITUTE(D$1,CHAR(10)," "),'Code_S01'!$H$2:$H$197,1) -> 3 | E3: =COUNTIFS('Code_S01'!$F$2:$F$197,SUBSTITUTE($A3,CHAR(10)," "),'Code_S01'!$G$2:$G$197,SUBSTITUTE(E$1,CHAR(10)," "),'Code_S01'!$H$2:$H$197,1) -> 1 | F3: =COUNTIFS('Code_S01'!$F$2:$F$197,SUBSTITUTE($A3,CHAR(10)," "),'Code_S01'!$G$2:$G$197,SUBSTITUTE(F$1,CHAR(10)," "),'Code_S01'!$H$2:$H$197,1) -> 5 | G3: =COUNTIFS('Code_S01'!$F$2:$F$197,SUBSTITUTE($A3,CHAR(10)," "),'Code_S01'!$G$2:$G$197,SUBSTITUTE(G$1,CHAR(10)," "),'Code_S01'!$H$2:$H$197,1) -> 0 | H3: =COUNTIFS('Code_S01'!$F$2:$F$197,SUBSTITUTE($A3,CHAR(10)," "),'Code_S01'!$G$2:$G$197,SUBSTITUTE(H$1,CHAR(10)," "),'Code_S01'!$H$2:$H$197,1) -> 0 | I3: =COUNTIFS('08_Study_Cohorts'!$A$2:$A$365,"S1",'08_Study_Cohorts'!$C$2:$C$365,SUBSTITUTE($A3,CHAR(10)," ")) -> 5
A4: 3D wound models | B4: =COUNTIFS('Code_S01'!$F$2:$F$197,SUBSTITUTE($A4,CHAR(10)," "),'Code_S01'!$G$2:$G$197,SUBSTITUTE(B$1,CHAR(10)," "),'Code_S01'!$H$2:$H$197,1) -> 8 | C4: =COUNTIFS('Code_S01'!$F$2:$F$197,SUBSTITUTE($A4,CHAR(10)," "),'Code_S01'!$G$2:$G$197,SUBSTITUTE(C$1,CHAR(10)," "),'Code_S01'!$H$2:$H$197,1) -> 8 | D4: =COUNTIFS('Code_S01'!$F$2:$F$197,SUBSTITUTE($A4,CHAR(10)," "),'Code_S01'!$G$2:$G$197,SUBSTITUTE(D$1,CHAR(10)," "),'Code_S01'!$H$2:$H$197,1) -> 1 | E4: =COUNTIFS('Code_S01'!$F$2:$F$197,SUBSTITUTE($A4,CHAR(10)," "),'Code_S01'!$G$2:$G$197,SUBSTITUTE(E$1,CHAR(10)," "),'Code_S01'!$H$2:$H$197,1) -> 5 | F4: =COUNTIFS('Code_S01'!$F$2:$F$197,SUBSTITUTE($A4,CHAR(10)," "),'Code_S01'!$G$2:$G$197,SUBSTITUTE(F$1,CHAR(10)," "),'Code_S01'!$H$2:$H$197,1) -> 7 | G4: =COUNTIFS('Code_S01'!$F$2:$F$197,SUBSTITUTE($A4,CHAR(10)," "),'Code_S01'!$G$2:$G$197,SUBSTITUTE(G$1,CHAR(10)," "),'Code_S01'!$H$2:$H$197,1) -> 2 | H4: =COUNTIFS('Code_S01'!$F$2:$F$197,SUBSTITUTE($A4,CHAR(10)," "),'Code_S01'!$G$2:$G$197,SUBSTITUTE(H$1,CHAR(10)," "),'Code_S01'!$H$2:$H$197,1) -> 2 | I4: =COUNTIFS('08_Study_Cohorts'!$A$2:$A$365,"S1",'08_Study_Cohorts'!$C$2:$C$365,SUBSTITUTE($A4,CHAR(10)," ")) -> 8
A5: Bioprinted models | B5: =COUNTIFS('Code_S01'!$F$2:$F$197,SUBSTITUTE($A5,CHAR(10)," "),'Code_S01'!$G$2:$G$197,SUBSTITUTE(B$1,CHAR(10)," "),'Code_S01'!$H$2:$H$197,1) -> 10 | C5: =COUNTIFS('Code_S01'!$F$2:$F$197,SUBSTITUTE($A5,CHAR(10)," "),'Code_S01'!$G$2:$G$197,SUBSTITUTE(C$1,CHAR(10)," "),'Code_S01'!$H$2:$H$197,1) -> 10 | D5: =COUNTIFS('Code_S01'!$F$2:$F$197,SUBSTITUTE($A5,CHAR(10)," "),'Code_S01'!$G$2:$G$197,SUBSTITUTE(D$1,CHAR(10)," "),'Code_S01'!$H$2:$H$197,1) -> 1 | E5: =COUNTIFS('Code_S01'!$F$2:$F$197,SUBSTITUTE($A5,CHAR(10)," "),'Code_S01'!$G$2:$G$197,SUBSTITUTE(E$1,CHAR(10)," "),'Code_S01'!$H$2:$H$197,1) -> 5 | F5: =COUNTIFS('Code_S01'!$F$2:$F$197,SUBSTITUTE($A5,CHAR(10)," "),'Code_S01'!$G$2:$G$197,SUBSTITUTE(F$1,CHAR(10)," "),'Code_S01'!$H$2:$H$197,1) -> 10 | G5: =COUNTIFS('Code_S01'!$F$2:$F$197,SUBSTITUTE($A5,CHAR(10)," "),'Code_S01'!$G$2:$G$197,SUBSTITUTE(G$1,CHAR(10)," "),'Code_S01'!$H$2:$H$197,1) -> 9 | H5: =COUNTIFS('Code_S01'!$F$2:$F$197,SUBSTITUTE($A5,CHAR(10)," "),'Code_S01'!$G$2:$G$197,SUBSTITUTE(H$1,CHAR(10)," "),'Code_S01'!$H$2:$H$197,1) -> 7 | I5: =COUNTIFS('08_Study_Cohorts'!$A$2:$A$365,"S1",'08_Study_Cohorts'!$C$2:$C$365,SUBSTITUTE($A5,CHAR(10)," ")) -> 10

Sheet Code_S02
A1: Main_ref | B1: SI_source_table | C1: SI_table_row | D1: Main_article_title | E1: DOI_in_main_register | F1: Group | G1: Domain | H1: Code_0_1 | I1: Proposed_structural_score | J1: Proposed_disease_score | K1: Provenance_note | L1: Source_URL | M1: Bibliography_title_match_pct | N1: Citation_present_in_main
A2: 105 | B2: S1 | C2: 2: Migration assay standardization | D2: Comparison of in vitro scratch wound assay experimental procedures | E2: 10.1016/j.bbrep.2023.101423 | F2: 2D early screening models | G2: Non-destructive same-sample serial tracking | H2: 1 | K2: IncuCyte repeated live-cell imaging every 4 h for 72 h (same monolayer). | L2: https://pmc.ncbi.nlm.nih.gov/articles/PMC9840221/ | M2: 100.0 | N2: YES
A3: 106 | B3: S1 | C3: 4: 2D assays with acute in vivo validation | D3: ERK activating peptide, AES16-2M promotes wound healing through accelerating migration of keratinocytes | E3: 10.1038/s41598-018-32851-y | F3: 2D early screening models | G3: 3+ sampling times | H3: 1 | K3: In vivo wound monitoring across days; 2D in-vitro assay is predominantly before/after. This uses study-level scope, not 2D-only scope. | L3: https://www.nature.com/articles/s41598-018-32851-y | M3: 100.0 | N3: YES
A4: 107 | B4: S1 | C4: 3: 2D therapeutic-response assays | D4: Effects of Periploca forrestii Schltr on wound healing by Src meditated Mek/Erk and PI3K/Akt signals | E4: 10.1016/j.jep.2019.03.046 | F4: 2D early screening models | G4: 3+ sampling times | H4: 1 | K4: Scratch images at 0,12,24,48 h and serial acute in vivo images. | L4: https://pubmed.ncbi.nlm.nih.gov/30905787/ | M4: 100.0 | N4: YES
A5: 108 | B5: S1 | C5: 2: Migration assay standardization | D5: Microscopy based methods for the assessment of epithelial cell migration during in vitro wound healing | E5: 10.3791/56799 | F5: 2D early screening models | G5: Two-point pre/post | H5: 1 | K5: Gap measured before/after (approximately 19 h), without a documented three-point series. | L5: https://pmc.ncbi.nlm.nih.gov/articles/PMC5908412/ | M5: 100.0 | N5: YES
A6: 109 | B6: S1 | C6: 3: 2D therapeutic-response assays | D6: Establishment of a cell-based wound healing assay for bio-relevant testing of wound therapeutics | E6: 10.1016/j.vascn.2017.10.003 | F6: 2D early screening models | G6: 3+ sampling times | H6: 1 | K6: Wound size measured serially up to 48-96 h. | L6: https://www.sciencedirect.com/science/article/abs/pii/S1056871917301363 | M6: 100.0 | N6: YES
A7: 110 | B7: S1 | C7: 6: Reconstructed epidermis for barrier and irritation testing | D7: Property characterization of reconstructed human epidermis equivalents, and performance as a skin irritation model | E7: 10.1016/j.tiv.2018.07.005 | F7: 3D epidermal models | G7: Endpoint-dominant | H7: 1 | K7: Culture followed over days, but wound/irritation effects are endpoint tests; culture age not time-depth. | L7: https://pubmed.ncbi.nlm.nih.gov/30053440/ | M7: 100.0 | N7: YES
A8: 111 | B8: S1 | C8: 6: Reconstructed epidermis for barrier and irritation testing | D8: A new reconstructed human epidermis for in vitro skin irritation testing | E8: 10.1016/j.tiv.2017.03.010 | F8: 3D epidermal models | G8: Endpoint-dominant | H8: 1 | K8: Repeated replicates are not outcome time-series; irritation has terminal viability. | L8: https://www.sciencedirect.com/science/article/pii/S0887233317300747 | M8: 100.0 | N8: YES
A9: 112 | B9: S1 | C9: 7: Epidermal and full-thickness toxicity comparison | D9: Skin corrosion test: A comparison between reconstructed human epidermis and full thickness skin models | E9: 10.1016/j.ejpb.2018.01.002 | F9: 3D epidermal models | G9: Endpoint-dominant | H9: 1 | K9: Different corrosive exposure durations are separate terminal tests, not a longitudinal response trajectory. | L9: https://www.sciencedirect.com/science/article/pii/S0939641117312821 | M9: 100.0 | N9: YES
A10: 115 | B10: S1 | C10: 7: Epidermal and full-thickness toxicity comparison | D10: Skin toxicity assessment of silver nanoparticles in a 3D epidermal model compared to 2D keratinocytes | E10: 10.2147/IJN.S225451 | F10: 3D epidermal models | G10: Endpoint-dominant | H10: 1 | K10: Acute 24 h nanoparticle exposure assessed at endpoint; culture duration does not count. | L10: https://pmc.ncbi.nlm.nih.gov/articles/PMC6910103/ | M10: 100.0 | N10: YES
A11: 122 | B11: S1 | C11: 10: Matrix-based 3D wound constructs | D11: Keratinocyte migration in a three-dimensional in vitro wound healing model co-cultured with fibroblasts | E11: 10.1007/s13770-018-0145-7 | F11: 3D wound models | G11: Non-destructive same-sample serial tracking | H11: 1 | K11: Bright-field keratinocyte migration followed daily in the SAME 3D culture (non-destructive), so score 3 rather than original score 2. | L11: https://pmc.ncbi.nlm.nih.gov/articles/PMC6250652/ | M11: 100.0 | N11: YES
A12: 118 | B12: S1 | C12: 11: Longitudinal non-invasive wound monitoring | D12: New Methodological Approach to Follow the Re‐Epithelialisation Phase in the Wound Healing Process on a 3D Full Thickness Skin Model | E12: 10.1111/exd.70137 | F12: 3D wound models | G12: Non-destructive same-sample serial tracking | H12: 1 | K12: Non-invasive OCT repeatedly evaluated the 3D wound model on D13-D17 and D20. | L12: https://onlinelibrary.wiley.com/doi/10.1111/exd.70137 | M12: 100.0 | N12: YES
A13: 119 | B13: S1 | C13: 8: Automated epidermal digital pathology | D13: Assessment of skin toxicity in an in vitro reconstituted human epidermis model using deep learning | E13: 10.1016/j.ajpath.2021.12.007 | F13: 3D epidermal models | G13: Endpoint-dominant | H13: 1 | K13: Drug dosed daily for four days but tissue thickness quantified at terminal histology only. | L13: https://www.sciencedirect.com/science/article/pii/S0002944022000074 | M13: 100.0 | N13: YES
... A29: 142 | B29: S1 | C29: 19: Disease-relevant diabetic bioprinted skin | D29: Engineering of diseased human skin equivalent using 3D cell printing for representing pathophysiological hallmarks of type 2 diabetes in vitro | E29: 10.1016/j.biomaterials.2021.120776 | F29: Bioprinted models | G29: 3+ sampling times | H29: 1 | K29: Metabolic/inflammatory measurements over 6,12,24 h and distinct treatment windows; no validated same-sample non-destructive wound trajectory. | L29: https://pubmed.ncbi.nlm.nih.gov/33798956/ | M29: 100.0 | N29: YES

Sheet Matrix_S02
A1: Model class | B1: Endpoint-dominant | C1: Two-point pre/post | D1: 3+ sampling times | E1: Non-destructive same-sample serial tracking | F1: Unique studies in class
A2: 2D early screening models | B2: =COUNTIFS('Code_S02'!$F$2:$F$29,SUBSTITUTE($A2,CHAR(10)," "),'Code_S02'!$G$2:$G$29,SUBSTITUTE(B$1,CHAR(10)," "),'Code_S02'!$H$2:$H$29,1) -> 0 | C2: =COUNTIFS('Code_S02'!$F$2:$F$29,SUBSTITUTE($A2,CHAR(10)," "),'Code_S02'!$G$2:$G$29,SUBSTITUTE(C$1,CHAR(10)," "),'Code_S02'!$H$2:$H$29,1) -> 1 | D2: =COUNTIFS('Code_S02'!$F$2:$F$29,SUBSTITUTE($A2,CHAR(10)," "),'Code_S02'!$G$2:$G$29,SUBSTITUTE(D$1,CHAR(10)," "),'Code_S02'!$H$2:$H$29,1) -> 3 | E2: =COUNTIFS('Code_S02'!$F$2:$F$29,SUBSTITUTE($A2,CHAR(10)," "),'Code_S02'!$G$2:$G$29,SUBSTITUTE(E$1,CHAR(10)," "),'Code_S02'!$H$2:$H$29,1) -> 1 | F2: =COUNTIFS('08_Study_Cohorts'!$A$2:$A$365,"S2",'08_Study_Cohorts'!$C$2:$C$365,SUBSTITUTE($A2,CHAR(10)," ")) -> 5
A3: 3D epidermal models | B3: =COUNTIFS('Code_S02'!$F$2:$F$29,SUBSTITUTE($A3,CHAR(10)," "),'Code_S02'!$G$2:$G$29,SUBSTITUTE(B$1,CHAR(10)," "),'Code_S02'!$H$2:$H$29,1) -> 5 | C3: =COUNTIFS('Code_S02'!$F$2:$F$29,SUBSTITUTE($A3,CHAR(10)," "),'Code_S02'!$G$2:$G$29,SUBSTITUTE(C$1,CHAR(10)," "),'Code_S02'!$H$2:$H$29,1) -> 0 | D3: =COUNTIFS('Code_S02'!$F$2:$F$29,SUBSTITUTE($A3,CHAR(10)," "),'Code_S02'!$G$2:$G$29,SUBSTITUTE(D$1,CHAR(10)," "),'Code_S02'!$H$2:$H$29,1) -> 0 | E3: =COUNTIFS('Code_S02'!$F$2:$F$29,SUBSTITUTE($A3,CHAR(10)," "),'Code_S02'!$G$2:$G$29,SUBSTITUTE(E$1,CHAR(10)," "),'Code_S02'!$H$2:$H$29,1) -> 0 | F3: =COUNTIFS('08_Study_Cohorts'!$A$2:$A$365,"S2",'08_Study_Cohorts'!$C$2:$C$365,SUBSTITUTE($A3,CHAR(10)," ")) -> 5
A4: 3D wound models | B4: =COUNTIFS('Code_S02'!$F$2:$F$29,SUBSTITUTE($A4,CHAR(10)," "),'Code_S02'!$G$2:$G$29,SUBSTITUTE(B$1,CHAR(10)," "),'Code_S02'!$H$2:$H$29,1) -> 0 | C4: =COUNTIFS('Code_S02'!$F$2:$F$29,SUBSTITUTE($A4,CHAR(10)," "),'Code_S02'!$G$2:$G$29,SUBSTITUTE(C$1,CHAR(10)," "),'Code_S02'!$H$2:$H$29,1) -> 0 | D4: =COUNTIFS('Code_S02'!$F$2:$F$29,SUBSTITUTE($A4,CHAR(10)," "),'Code_S02'!$G$2:$G$29,SUBSTITUTE(D$1,CHAR(10)," "),'Code_S02'!$H$2:$H$29,1) -> 4 | E4: =COUNTIFS('Code_S02'!$F$2:$F$29,SUBSTITUTE($A4,CHAR(10)," "),'Code_S02'!$G$2:$G$29,SUBSTITUTE(E$1,CHAR(10)," "),'Code_S02'!$H$2:$H$29,1) -> 4 | F4: =COUNTIFS('08_Study_Cohorts'!$A$2:$A$365,"S2",'08_Study_Cohorts'!$C$2:$C$365,SUBSTITUTE($A4,CHAR(10)," ")) -> 8
A5: Bioprinted models | B5: =COUNTIFS('Code_S02'!$F$2:$F$29,SUBSTITUTE($A5,CHAR(10)," "),'Code_S02'!$G$2:$G$29,SUBSTITUTE(B$1,CHAR(10)," "),'Code_S02'!$H$2:$H$29,1) -> 0 | C5: =COUNTIFS('Code_S02'!$F$2:$F$29,SUBSTITUTE($A5,CHAR(10)," "),'Code_S02'!$G$2:$G$29,SUBSTITUTE(C$1,CHAR(10)," "),'Code_S02'!$H$2:$H$29,1) -> 0 | D5: =COUNTIFS('Code_S02'!$F$2:$F$29,SUBSTITUTE($A5,CHAR(10)," "),'Code_S02'!$G$2:$G$29,SUBSTITUTE(D$1,CHAR(10)," "),'Code_S02'!$H$2:$H$29,1) -> 10 | E5: =COUNTIFS('Code_S02'!$F$2:$F$29,SUBSTITUTE($A5,CHAR(10)," "),'Code_S02'!$G$2:$G$29,SUBSTITUTE(E$1,CHAR(10)," "),'Code_S02'!$H$2:$H$29,1) -> 0 | F5: =COUNTIFS('08_Study_Cohorts'!$A$2:$A$365,"S2",'08_Study_Cohorts'!$C$2:$C$365,SUBSTITUTE($A5,CHAR(10)," ")) -> 10

Sheet Code_S03
A1: Main_ref | B1: SI_source_table | C1: SI_table_row | D1: Main_article_title | E1: DOI_in_main_register | F1: Group | G1: Domain | H1: Code_0_1 | I1: Proposed_structural_score | J1: Proposed_disease_score | K1: Provenance_note | L1: Source_URL | M1: Bibliography_title_match_pct | N1: Citation_present_in_main
A2: 166 | B2: S2 | C2: 7: Perfused reconstructed skin-on-chip for transdermal diffusion | D2: In silico approach for validating organ-on-chips: exemplifying through a skin-on-chip device | E2: 10.1007/s10404-025-02863-y | F2: Barrier/permeation exposure | G2: Barrier or permeation | H2: 1 | K2: Provided article-level Table S2 coding (renumbered to current main bibliography) | L2: https://doi.org/10.1007/s10404-025-02863-y | M2: 100.0 | N2: YES
A3: 181 | B3: S2 | C3: 8: Perfused 3D skin-on-chip for barrier validation and drug permeation | D3: A 3D microfluidic model for preclinical drug permeation studies: Advancing validation of skin-on-chip technology | E3: 10.1016/j.jpba.2025.117187 | F3: Barrier/permeation exposure | G3: Barrier or permeation | H3: 1 | K3: Provided article-level Table S2 coding (renumbered to current main bibliography) | L3: https://doi.org/10.1016/j.jpba.2025.117187 | M3: 100.0 | N3: YES
A4: 192 | B4: S2 | C4: 9: Ex vivo and surrogate skin dynamic permeation platforms | D4: Skin-on-a-chip device for ex vivo monitoring of transdermal delivery of drugs—design, fabrication, and testing | E4: 10.3390/pharmaceutics11090445 | F4: Barrier/permeation exposure | G4: Barrier or permeation | H4: 1 | K4: Provided article-level Table S2 coding (renumbered to current main bibliography) | L4: https://doi.org/10.3390/pharmaceutics11090445 | M4: 100.0 | N4: YES
A5: 193 | B5: S2 | C5: 9: Ex vivo and surrogate skin dynamic permeation platforms | D5: Comparison between Franz diffusion cell and a novel micro-physiological system for in vitro penetration assay using different skin models | E5: 10.1016/j.slast.2021.12.006 | F5: Barrier/permeation exposure | G5: Barrier or permeation | H5: 1 | K5: Provided article-level Table S2 coding (renumbered to current main bibliography) | L5: https://doi.org/10.1016/j.slast.2021.12.006 | M5: 100.0 | N5: YES
A6: 194 | B6: S2 | C6: 10: Skin-linked systemic toxicity chips | D6: Microphysiological heart–liver body-on-a-chip system with a skin mimic for evaluating topical drug delivery | E6: 10.1039/c9lc00861f | F6: Barrier/permeation exposure | G6: Barrier or permeation | H6: 1 | K6: Provided article-level Table S2 coding (renumbered to current main bibliography) | L6: https://doi.org/10.1039/c9lc00861f | M6: 100.0 | N6: YES
A7: 195 | B7: S2 | C7: 10: Skin-linked systemic toxicity chips | D7: Toxicity of topically applied drugs beyond skin irritation: Static skin model vs | E7: 10.1016/j.ijpharm.2020.119788 | F7: Barrier/permeation exposure | G7: Barrier or permeation | H7: 1 | K7: Provided article-level Table S2 coding (renumbered to current main bibliography) | L7: https://doi.org/10.1016/j.ijpharm.2020.119788 | M7: 100.0 | N7: YES
A8: 166 | B8: S2 | C8: 7: Perfused reconstructed skin-on-chip for transdermal diffusion | D8: In silico approach for validating organ-on-chips: exemplifying through a skin-on-chip device | E8: 10.1007/s10404-025-02863-y | F8: Barrier/permeation exposure | G8: Flow or perfusion control | H8: 1 | K8: Provided article-level Table S2 coding (renumbered to current main bibliography) | L8: https://doi.org/10.1007/s10404-025-02863-y | M8: 100.0 | N8: YES
A9: 181 | B9: S2 | C9: 8: Perfused 3D skin-on-chip for barrier validation and drug permeation | D9: A 3D microfluidic model for preclinical drug permeation studies: Advancing validation of skin-on-chip technology | E9: 10.1016/j.jpba.2025.117187 | F9: Barrier/permeation exposure | G9: Flow or perfusion control | H9: 1 | K9: Provided article-level Table S2 coding (renumbered to current main bibliography) | L9: https://doi.org/10.1016/j.jpba.2025.117187 | M9: 100.0 | N9: YES
A10: 192 | B10: S2 | C10: 9: Ex vivo and surrogate skin dynamic permeation platforms | D10: Skin-on-a-chip device for ex vivo monitoring of transdermal delivery of drugs—design, fabrication, and testing | E10: 10.3390/pharmaceutics11090445 | F10: Barrier/permeation exposure | G10: Flow or perfusion control | H10: 1 | K10: Provided article-level Table S2 coding (renumbered to current main bibliography) | L10: https://doi.org/10.3390/pharmaceutics11090445 | M10: 100.0 | N10: YES
A11: 193 | B11: S2 | C11: 9: Ex vivo and surrogate skin dynamic permeation platforms | D11: Comparison between Franz diffusion cell and a novel micro-physiological system for in vitro penetration assay using different skin models | E11: 10.1016/j.slast.2021.12.006 | F11: Barrier/permeation exposure | G11: Flow or perfusion control | H11: 1 | K11: Provided article-level Table S2 coding (renumbered to current main bibliography) | L11: https://doi.org/10.1016/j.slast.2021.12.006 | M11: 100.0 | N11: YES
A12: 194 | B12: S2 | C12: 10: Skin-linked systemic toxicity chips | D12: Microphysiological heart–liver body-on-a-chip system with a skin mimic for evaluating topical drug delivery | E12: 10.1039/c9lc00861f | F12: Barrier/permeation exposure | G12: Flow or perfusion control | H12: 1 | K12: Provided article-level Table S2 coding (renumbered to current main bibliography) | L12: https://doi.org/10.1039/c9lc00861f | M12: 100.0 | N12: YES
A13: 195 | B13: S2 | C13: 10: Skin-linked systemic toxicity chips | D13: Toxicity of topically applied drugs beyond skin irritation: Static skin model vs | E13: 10.1016/j.ijpharm.2020.119788 | F13: Barrier/permeation exposure | G13: Flow or perfusion control | H13: 1 | K13: Provided article-level Table S2 coding (renumbered to current main bibliography) | L13: https://doi.org/10.1016/j.ijpharm.2020.119788 | M13: 100.0 | N13: YES
... A26: 164 | B26: S2 | C26: 5: Oxygen-gradient angiogenesis module | D26: Studying sprouting angiogenesis under combination of oxygen gradients and co-culture of fibroblasts using microfluidic cell culture model | E26: 10.1016/j.mtbio.2023.100703 | F26: Controlled microfluidic perturbation | G26: Oxygen or angiogenic cues | H26: 1 | K26: Provided article-level Table S2 coding (renumbered to current main bibliography) | L26: https://doi.org/10.1016/j.mtbio.2023.100703 | M26: 100.0 | N26: YES
A27: 58 | B27: S2 | C27: 12: Perfused inflammatory full-thickness skin-on-chip model for drug-response testing | D27: Analysis of drug efficacy for inflammatory skin on an organ-chip system | F27: Disease/immune programming | G27: Barrier or permeation | H27: 1 | K27: Source-specific correction from Quan et al. 2022, not Gard et al. 2023; full-text primary source verified. Provided article-level Table S2 coding (renumbered to current main bibliography) | L27: https://doi.org/10.3389/fbioe.2022.939629 | M27: 100.0 | N27: YES
A28: 169 | B28: S2 | C28: 13: Infection-activated vessel-on-chip | D28: An in vitro human vessel model to study Neisseria meningitidis colonization and vascular damages | E28: 10.7554/eLife.107813 | F28: Disease/immune programming | G28: Barrier or permeation | H28: 1 | K28: Provided article-level Table S2 coding (renumbered to current main bibliography) | L28: https://doi.org/10.7554/eLife.107813 | M28: 100.0 | N28: YES
A29: 198 | B29: S2 | C29: 16: Epidermal pruritus and barrier-support skin-on-chip | D29: Skin-on-Chip and clinical evaluation of the soothing potential of a topical natural treatment for atopic-prone skin: An exploratory study | E29: 10.1016/j.biopha.2025.118957 | F29: Disease/immune programming | G29: Barrier or permeation | H29: 1 | K29: Provided article-level Table S2 coding (renumbered to current main bibliography) | L29: https://doi.org/10.1016/j.biopha.2025.118957 | M29: 100.0 | N29: YES
A30: 58 | B30: S2 | C30: 12: Perfused inflammatory full-thickness skin-on-chip model for drug-response testing | D30: Analysis of drug efficacy for inflammatory skin on an organ-chip system | F30: Disease/immune programming | G30: Flow or perfusion control | H30: 1 | K30: Source-specific correction from Quan et al. 2022, not Gard et al. 2023; full-text primary source verified. Provided article-level Table S2 coding (renumbered to current main bibliography) | L30: https://doi.org/10.3389/fbioe.2022.939629 | M30: 100.0 | N30: YES
A31: 169 | B31: S2 | C31: 13: Infection-activated vessel-on-chip | D31: An in vitro human vessel model to study Neisseria meningitidis colonization and vascular damages | E31: 10.7554/eLife.107813 | F31: Disease/immune programming | G31: Flow or perfusion control | H31: 1 | K31: Provided article-level Table S2 coding (renumbered to current main bibliography) | L31: https://doi.org/10.7554/eLife.107813 | M31: 100.0 | N31: YES
A32: 196 | B32: S2 | C32: 14: Dynamic reconstructed skin-on-chip for topical sensitizer response | D32: Proof-of-concept organ-on-chip study: topical cinnamaldehyde exposure of reconstructed human skin with integrated neopapillae cultured under dynamic flow | E32: 10.3390/pharmaceutics14081529 | F32: Disease/immune programming | G32: Flow or perfusion control | H32: 1 | K32: Provided article-level Table S2 coding (renumbered to current main bibliography) | L32: https://doi.org/10.3390/pharmaceutics14081529 | M32: 100.0 | N32: YES
A33: 197 | B33: S2 | C33: 15: Perfused inflammatory skin-on-chip with rapid cytokine detection | D33: Skin-on-a-Chip Coupled with a Rapid Inflammation Detection System for Cosmetic Ingredient Screening | F33: Disease/immune programming | G33: Flow or perfusion control | H33: 1 | K33: Provided article-level Table S2 coding (renumbered to current main bibliography) | M33: 100.0 | N33: YES
A34: 198 | B34: S2 | C34: 16: Epidermal pruritus and barrier-support skin-on-chip | D34: Skin-on-Chip and clinical evaluation of the soothing potential of a topical natural treatment for atopic-prone skin: An exploratory study | E34: 10.1016/j.biopha.2025.118957 | F34: Disease/immune programming | G34: Flow or perfusion control | H34: 1 | K34: Provided article-level Table S2 coding (renumbered to current main bibliography) | L34: https://doi.org/10.1016/j.biopha.2025.118957 | M34: 100.0 | N34: YES
A35: 169 | B35: S2 | C35: 13: Infection-activated vessel-on-chip | D35: An in vitro human vessel model to study Neisseria meningitidis colonization and vascular damages | E35: 10.7554/eLife.107813 | F35: Disease/immune programming | G35: Infection or microbial state | H35: 1 | K35: Provided article-level Table S2 coding (renumbered to current main bibliography) | L35: https://doi.org/10.7554/eLife.107813 | M35: 100.0 | N35: YES
A36: 58 | B36: S2 | C36: 12: Perfused inflammatory full-thickness skin-on-chip model for drug-response testing | D36: Analysis of drug efficacy for inflammatory skin on an organ-chip system | F36: Disease/immune programming | G36: Inflammation or immune state | H36: 1 | K36: Source-specific correction from Quan et al. 2022, not Gard et al. 2023; full-text primary source verified. Provided article-level Table S2 coding (renumbered to current main bibliography) | L36: https://doi.org/10.3389/fbioe.2022.939629 | M36: 100.0 | N36: YES
A37: 169 | B37: S2 | C37: 13: Infection-activated vessel-on-chip | D37: An in vitro human vessel model to study Neisseria meningitidis colonization and vascular damages | E37: 10.7554/eLife.107813 | F37: Disease/immune programming | G37: Inflammation or immune state | H37: 1 | K37: Provided article-level Table S2 coding (renumbered to current main bibliography) | L37: https://doi.org/10.7554/eLife.107813 | M37: 100.0 | N37: YES
A38: 196 | B38: S2 | C38: 14: Dynamic reconstructed skin-on-chip for topical sensitizer response | D38: Proof-of-concept organ-on-chip study: topical cinnamaldehyde exposure of reconstructed human skin with integrated neopapillae cultured under dynamic flow | E38: 10.3390/pharmaceutics14081529 | F38: Disease/immune programming | G38: Inflammation or immune state | H38: 1 | K38: Provided article-level Table S2 coding (renumbered to current main bibliography) | L38: https://doi.org/10.3390/pharmaceutics14081529 | M38: 100.0 | N38: YES
A39: 197 | B39: S2 | C39: 15: Perfused inflammatory skin-on-chip with rapid cytokine detection | D39: Skin-on-a-Chip Coupled with a Rapid Inflammation Detection System for Cosmetic Ingredient Screening | F39: Disease/immune programming | G39: Inflammation or immune state | H39: 1 | K39: Provided article-level Table S2 coding (renumbered to current main bibliography) | M39: 100.0 | N39: YES
A40: 198 | B40: S2 | C40: 16: Epidermal pruritus and barrier-support skin-on-chip | D40: Skin-on-Chip and clinical evaluation of the soothing potential of a topical natural treatment for atopic-prone skin: An exploratory study | E40: 10.1016/j.biopha.2025.118957 | F40: Disease/immune programming | G40: Inflammation or immune state | H40: 1 | K40: Provided article-level Table S2 coding (renumbered to current main bibliography) | L40: https://doi.org/10.1016/j.biopha.2025.118957 | M40: 100.0 | N40: YES
A41: 101 | B41: S2 | C41: 18: Multiplexed wound-exudate sensing patches | D41: A flexible multiplexed immunosensor for point-of-care in situ wound monitoring | E41: 10.1126/sciadv.abg9614 | F41: Wound-state sensing | G41: Infection or microbial state | H41: 1 | K41: Provided article-level Table S2 coding (renumbered to current main bibliography) | L41: https://doi.org/10.1126/sciadv.abg9614 | M41: 100.0 | N41: YES
A42: 101 | B42: S2 | C42: 18: Multiplexed wound-exudate sensing patches | D42: A flexible multiplexed immunosensor for point-of-care in situ wound monitoring | E42: 10.1126/sciadv.abg9614 | F42: Wound-state sensing | G42: Inflammation or immune state | H42: 1 | K42: Provided article-level Table S2 coding (renumbered to current main bibliography) | L42: https://doi.org/10.1126/sciadv.abg9614 | M42: 100.0 | N42: YES
A43: 101 | B43: S2 | C43: 18: Multiplexed wound-exudate sensing patches | D43: A flexible multiplexed immunosensor for point-of-care in situ wound monitoring | E43: 10.1126/sciadv.abg9614 | F43: Wound-state sensing | G43: Metabolic or biochemical sensing | H43: 1 | K43: Provided article-level Table S2 coding (renumbered to current main bibliography) | L43: https://doi.org/10.1126/sciadv.abg9614 | M43: 100.0 | N43: YES
A44: 182 | B44: S2 | C44: 18: Multiplexed wound-exudate sensing patches | D44: A flexible and multimodal biosensing patch integrated with microfluidics for chronic wound monitoring | E44: 10.1016/j.cej.2024.157673 | F44: Wound-state sensing | G44: Metabolic or biochemical sensing | H44: 1 | K44: Provided article-level Table S2 coding (renumbered to current main bibliography) | L44: https://doi.org/10.1016/j.cej.2024.157673 | M44: 100.0 | N44: YES
